{"name": "test_b", "status": "skipped", "statusDetails": {"message": "AssertionError: assert 0", "trace": "self = <Test_App5.Test_ABC object at 0x0828D8D0>\n\n    @pytest.mark.xfail(2 > 1, reason=\"标注为预期失败\") # 标记为预期失败函数test_b\n    def test_b(self):\n        print(\"------->test_b\")\n>       assert 0\nE       assert 0\n\nTest_App5.py:14: AssertionError"}, "start": 1602663054685, "stop": 1602663054685, "uuid": "e40ae86f-24cc-4fa1-9006-5248a1b8a346", "historyId": "02ec5513fe8c67f3f444c5658bcbbcdc", "testCaseId": "c8c20521d02f46a9c22d349c9b0f5dc3", "fullName": "clsp.Test_App5.Test_ABC#test_b", "labels": [{"name": "tag", "value": "@pytest.mark.xfail(True, reason='标注为预期失败')"}, {"name": "parentSuite", "value": "clsp"}, {"name": "suite", "value": "Test_App5"}, {"name": "subSuite", "value": "Test_ABC"}, {"name": "host", "value": "LAPTOP-LFNOOUSC"}, {"name": "thread", "value": "14328-MainThread"}, {"name": "framework", "value": "pytest"}, {"name": "language", "value": "cpython3"}, {"name": "package", "value": "clsp.Test_App5"}]}